Workbook

Sheet 7-11
A1: Согласовано: | H1: Утверждаю
A2: Директор МБОУ СОШ №4 | H2: зав.производством ООО "МТК"
A3: _______ Н.В. Менщикова | H3: __________Р.Г. Сахауова
A4: 46034 | C4: понедельник | G4: неделя 1
A5: неделя 1 | C5: возрастная категория 7-11
A6: Прием пищи | B6: № рец. | C6: Блюдо | D6: Выход, г | E6: Калорийн | F6: Белки | G6: Жиры | H6: Углеводы
A7: Завтрак
B8: 98 | C8: Каша рисовая молочная жидкая со слив. маслом | D8: 205 | E8: 298.8 | F8: 7.5 | G8: 10 | H8: 42.9
B9: 10 | C9: Бутерброд горячий с сыром | D9: 43 | E9: 124.8 | F9: 5.8 | G9: 6 | H9: 13.7
B10: 82 | C10: Фрукты свежие (яблоко) | D10: 120 | E10: 56.4 | F10: 0.5 | G10: 0.5 | H10: 11.8
B11: 459 | C11: Чай с лимоном | D11: 207 | E11: 43.4 | F11: 0.3 | G11: 0 | H11: 10.3
B12: 573 | C12: Хлеб пшеничный витаминный | D12: 25 | E12: 60.5 | F12: 2 | G12: 0 | H12: 12.2
B13: 574 | C13: Хлеб ржаной | D13: 25 | E13: 64.8 | F13: 2.1 | G13: 1 | H13: 12.7
C14: Итого | D14: =SUM(D8:D13) -> 625 | E14: =SUM(E8:E13) -> 648.7 | F14: =SUM(F8:F13) -> 18.2 | G14: =SUM(G8:G13) -> 17.5 | H14: =SUM(H8:H13) -> 103.6
A15: Обед
B16: 28.1 | C16: Салат из кукурузы со св.огурцом, яйцом и сыром | D16: 60 | E16: 82.3 | F16: 3.8 | G16: 6 | H16: 3.3
B17: 139 | C17: Суп картофельный с горохом, с мясом говядины, гренками | D17: 225 | E17: 196 | F17: 10.31 | G17: 6.29 | H17: 24.52
B18: 476 | C18: Котлета Домашняя | D18: 90 | E18: 254.3 | F18: 17 | G18: 11 | H18: 28.7
B19: 516 | C19: Макаронные изделия отварные | D19: 150 | E19: 204.3 | F19: 5.44 | G19: 4.84 | H19: 34.71
B20: 699 | C20: Напиток апельсиновый | D20: 200 | E20: 105 | F20: 0.2 | G20: 0 | H20: 24.5
B21: 573 | C21: Хлеб пшеничный витаминный | D21: 25 | E21: 60.5 | F21: 2 | G21: 0 | H21: 12.2
B22: 574 | C22: Хлеб ржаной | D22: 25 | E22: 64.8 | F22: 2.1 | G22: 1 | H22: 12.7
C23: Итого | D23: =SUM(D16:D22) -> 775 | E23: =SUM(E16:E22) -> 967.2 | F23: =SUM(F16:F22) -> 40.85 | G23: =SUM(G16:G22) -> 29.13 | H23: =SUM(H16:H22) -> 140.63
A24: Полдник
B25: 747 | C25: Сосиска запеченая в тесте | D25: 120 | E25: 339.14 | F25: 11.74 | G25: 17.1 | H25: 34.61
B26: 82 | C26: Фрукты свежие (яблоко) | D26: 120 | E26: 56.4 | F26: 0.5 | G26: 0.5 | H26: 11.8
B27: 459 | C27: Чай с лимоном | D27: 207 | E27: 43.4 | F27: 0.3 | G27: 0 | H27: 10.3
C28: Итого | D28: =SUM(D25:D27) -> 447 | E28: =SUM(E25:E27) -> 438.94 | F28: =SUM(F25:F27) -> 12.54 | G28: =SUM(G25:G27) -> 17.6 | H28: =SUM(H25:H27) -> 56.71
C29: Всего: | E29: =E14+E23+E28 -> 2054.84 | F29: =F14+F23+F28 -> 71.59 | G29: =G14+G23+G28 -> 64.23 | H29: =H14+H23+H28 -> 300.94
A31: Согласовано: | H31: Утверждаю
A32: Директор МБОУ СОШ №4 | H32: зав.производством ООО "МТК"
A33: _______Н.В. Менщикова | H33: __________Р.Г. Сахауова
A34: 46035 | C34: вторник | G34: неделя 1
A35: неделя 1 | C35: возрастная категория 7-11
A36: Прием пищи | B36: № рец. | C36: Блюдо | D36: Выход, г | E36: Калорийн | F36: Белки | G36: Жиры | H36: Углеводы
A37: Завтрак
B38: 53 | C38: Огурец свежий порционно | D38: 30 | E38: 4.1 | F38: 0.2 | G38: 0 | H38: 0.7
B39: 595 | C39: Наггетсы | D39: 60 | E39: 171.1 | F39: 10.4 | G39: 11.2 | H39: 7.2
B40: 516 | C40: Макаронные изделия отварные | D40: 150 | E40: 204.32 | F40: 5.44 | G40: 4.84 | H40: 34.71
B41: 82/1 | C41: Фрукты свежие (банан) | D41: 180 | E41: 91.2 | F41: 0.8 | G41: 0.6 | H41: 20
...

Sheet 12 лет
A1: Согласовано: | H1: Утверждаю
A2: Директор МБОУ СОШ №4 | H2: зав.производством ООО "МТК"
A3: _______ Н.В. Менщикова | H3: __________Р.Г. Сахауова
A4: ='7-11'!A4 -> 46034 | C4: понедельник | G4: неделя 1
A5: неделя 1 | C5: возрастная категория 12 и старше
A6: Прием пищи | B6: № рец. | C6: Блюдо | D6: Выход, г | E6: Калорийн | F6: Белки | G6: Жиры | H6: Углеводы
A7: Завтрак
B8: 98 | C8: Каша рисовая молочная жидкая со слив. маслом | D8: 205 | E8: 298.8 | F8: 7.5 | G8: 10 | H8: 42.9
B9: 10 | C9: Бутерброд горячий с сыром | D9: 50 | E9: 124.8 | F9: 5.8 | G9: 6 | H9: 13.7
B10: 82 | C10: Фрукты свежие (яблоко) | D10: 120 | E10: 56.4 | F10: 0.5 | G10: 0.5 | H10: 11.8
B11: 459 | C11: Чай с лимоном | D11: 207 | E11: 43.4 | F11: 0.3 | G11: 0 | H11: 10.3
B12: 573 | C12: Хлеб пшеничный витаминный | D12: 25 | E12: 60.5 | F12: 2 | G12: 0 | H12: 12.2
B13: 574 | C13: Хлеб ржаной | D13: 25 | E13: 64.8 | F13: 2.1 | G13: 1 | H13: 12.7
C14: Итого | D14: =SUM(D8:D13) -> 632 | E14: =SUM(E8:E13) -> 648.7 | F14: =SUM(F8:F13) -> 18.2 | G14: =SUM(G8:G13) -> 17.5 | H14: =SUM(H8:H13) -> 103.6
A15: Обед
B16: 28.1 | C16: Салат из кукурузы со св.огурцом, яйцом и сыром | D16: 100 | E16: 137.2 | F16: 6.3 | G16: 10 | H16: 5.5
B17: 139 | C17: Суп картофельный с горохом, с мясом говядины, гренками | D17: 275 | E17: 239.59 | F17: 12.6 | G17: 7.69 | H17: 29.97
B18: 476 | C18: Котлета Домашняя | D18: 100 | E18: 282.38 | F18: 13.49 | G18: 12.36 | H18: 29.66
B19: 516 | C19: Макаронные изделия отварные | D19: 180 | E19: 245.2 | F19: 6.5 | G19: 5.8 | H19: 41.6
B20: 699 | C20: Напиток апельсиновый | D20: 200 | E20: 105 | F20: 0.2 | G20: 0 | H20: 24.5
B21: 573 | C21: Хлеб пшеничный витаминный | D21: 25 | E21: 60.5 | F21: 2 | G21: 0 | H21: 12.2
B22: 574 | C22: Хлеб ржаной | D22: 25 | E22: 64.8 | F22: 2.1 | G22: 1 | H22: 12.7
C23: Итого | D23: =SUM(D16:D22) -> 905 | E23: =SUM(E16:E22) -> 1134.67 | F23: =SUM(F16:F22) -> 43.19 | G23: =SUM(G16:G22) -> 36.85 | H23: =SUM(H16:H22) -> 156.13
A24: Полдник
B25: 747 | C25: Сосиска запеченая в тесте | D25: 120 | E25: 339.14 | F25: 11.74 | G25: 17.1 | H25: 34.61
B26: 82 | C26: Фрукты свежие (яблоко) | D26: 120 | E26: 56.4 | F26: 0.5 | G26: 0.5 | H26: 11.8
B27: 459 | C27: Чай с лимоном | D27: 207 | E27: 43.4 | F27: 0.3 | G27: 0 | H27: 10.3
C28: Итого | D28: =SUM(D25:D27) -> 447 | E28: =SUM(E25:E27) -> 438.94 | F28: =SUM(F25:F27) -> 12.54 | G28: =SUM(G25:G27) -> 17.6 | H28: =SUM(H25:H27) -> 56.71
C29: Всего: | E29: =E14+E23+E28 -> 2222.31 | F29: =F14+F23+F28 -> 73.93 | G29: =G14+G23+G28 -> 71.95 | H29: =H14+H23+H28 -> 316.44
A31: Согласовано: | H31: Утверждаю
A32: Директор МБОУ СОШ №4 | H32: зав.производством ООО "МТК"
A33: _______Н.В. Менщикова | H33: __________Р.Г. Сахауова
A34: ='7-11'!A34 -> 46035 | C34: вторник | G34: неделя 1
A35: неделя 1 | C35: возрастная категория 12 и старше
A36: Прием пищи | B36: № рец. | C36: Блюдо | D36: Выход, г | E36: Калорийн | F36: Белки | G36: Жиры | H36: Углеводы
A37: Завтрак
B38: 53 | C38: Огурец свежий порционно | D38: 30 | E38: 4.1 | F38: 0.2 | G38: 0 | H38: 0.7
B39: 595 | C39: Наггетсы | D39: 60 | E39: 171.1 | F39: 10.4 | G39: 11.2 | H39: 7.2
B40: 516 | C40: Макаронные изделия отварные | D40: 180 | E40: 245.2 | F40: 6.5 | G40: 5.8 | H40: 41.6
B41: 82/1 | C41: Фрукты свежие (банан) | D41: 180 | E41: 91.2 | F41: 0.8 | G41: 0.6 | H41: 20
...

Sheet диабет 7-11 лет
A1: Согласовано: | H1: Утверждаю
A2: Директор МБОУ СОШ №4 | H2: зав.производством ООО "МТК"
A3: _______ Н.В. Менщикова | H3: __________Р.Г. Сахауова
A4: ='7-11'!A4 -> 46034 | C4: понедельник | G4: неделя 1
A5: неделя 1 | C5: Диабет 7-11 лет
A6: Прием пищи | B6: № рец. | C6: Блюдо | D6: Выход, г | E6: Калорийн | F6: Белки | G6: Жиры | H6: Углеводы
A7: Завтрак
B8: 453 | C8: Каша геркулес молочная б/сахара | D8: 200 | E8: 168.74 | F8: 5.34 | G8: 2.9 | H8: 30.32
B9: 34 | C9: Бутерброд горячий с сыром | D9: 45 | E9: 142.6 | F9: 5 | G9: 8.6 | H9: 10.8
B10: 82 | C10: Фрукты свежие (яблоко) | D10: 100 | E10: 47 | F10: 0.4 | G10: 0.4 | H10: 9.8
B11: 740.1 | C11: Чай с лимоном б/сахара | D11: 200 | E11: 2.4 | F11: 0.2 | G11: 0 | H11: 0.4
B12: 267 | C12: Яйцо вареное | D12: 40 | E12: 63 | F12: 5 | G12: 5 | H12: 0.3
B13: 574 | C13: Хлеб ржаной | D13: 30 | E13: 30.6 | F13: 1 | G13: 0.15 | H13: 6.35
C14: Итого | D14: =SUM(D8:D13) -> 615 | E14: =SUM(E8:E13) -> 454.34 | F14: =SUM(F8:F13) -> 16.94 | G14: =SUM(G8:G13) -> 17.05 | H14: =SUM(H8:H13) -> 57.97
A15: Обед
B16: 53 | C16: Огурцы свежие порционно | D16: 60 | E16: 8.04 | F16: 0.2 | G16: 0 | H16: 0
B17: 139 | C17: Суп картофельный с горохом, с мясом говядины, гренками | D17: 225 | E17: 196 | F17: 10.3 | G17: 6.3 | H17: 24.5
B18: 476 | C18: Котлета Домашняя | D18: 90 | E18: 254.3 | F18: 17 | G18: 11 | H18: 28.7
B19: 114 | C19: Каша перловая рассыпчатая | D19: 150 | E19: 186 | F19: 4.51 | G19: 4.24 | H19: 32.44
B20: 699.01 | C20: Напиток апельсиновый б/сахара | D20: 200 | E20: 80 | F20: 0.2 | G20: 0 | H20: 4.5
B21: 574 | C21: Хлеб ржаной | D21: 30 | E21: 30.6 | F21: 1 | G21: 0.15 | H21: 6.35
C22: Итого | D22: =SUM(D16:D21) -> 755 | E22: =SUM(E16:E21) -> 754.94 | F22: =SUM(F16:F21) -> 33.21 | G22: =SUM(G16:G21) -> 21.69 | H22: =SUM(H16:H21) -> 96.49
A23: Полдник
B24: 269 | C24: Омлет запеченый с зеленым горошком | D24: 150 | E24: 215.6 | F24: 11 | G24: 16.6 | H24: 5.4
B25: 82 | C25: Фрукты свежие (яблоко) | D25: 100 | E25: 47 | F25: 0.4 | G25: 0.4 | H25: 9.8
B26: 268 | C26: Кефир | D26: 200 | E26: 100 | F26: 5.8 | G26: 5 | H26: 8
B27: 574 | C27: Хлеб ржаной | D27: 30 | E27: 30.6 | F27: 1 | G27: 0.15 | H27: 6.35
C28: Итого | D28: =SUM(D24:D27) -> 480 | E28: =SUM(E24:E27) -> 393.2 | F28: =SUM(F24:F27) -> 18.2 | G28: =SUM(G24:G27) -> 22.15 | H28: =SUM(H24:H27) -> 29.55
C29: Всего: | E29: =E14+E22+E28 -> 1602.48 | F29: =F14+F22+F28 -> 68.35 | G29: =G14+G22+G28 -> 60.89 | H29: =H14+H22+H28 -> 184.01
A31: Согласовано: | H31: Утверждаю
A32: Директор МБОУ СОШ №4 | H32: зав.производством ООО "МТК"
A33: _______Н.В. Менщикова | H33: __________Р.Г. Сахауова
A34: ='7-11'!A34 -> 46035 | C34: вторник | G34: неделя 1
A35: неделя 1 | C35: Диабет 7-11 лет
A36: Прием пищи | B36: № рец. | C36: Блюдо | D36: Выход, г | E36: Калорийн | F36: Белки | G36: Жиры | H36: Углеводы
A37: Завтрак
B38: 53 | C38: Огурец свежий порционно | D38: 30 | E38: 4.1 | F38: 0.2 | G38: 0 | H38: 0.7
B39: 503 | C39: Омлет натуральный паровой | D39: 150 | E39: 199.22 | F39: 13.44 | G39: 14.66 | H39: 4.38
B40: 540 | C40: Сыр порционно | D40: 20 | E40: 71.6 | F40: 4.6 | G40: 5.9 | H40: 0
B41: 82/3 | C41: Фрукты свежие (мандарин) | D41: 100 | E41: 38 | F41: 0.8 | G41: 0.2 | H41: 7.5
...

Sheet диабет 12 лет
A1: Согласовано: | H1: Утверждаю
A2: Директор МБОУ СОШ №4 | H2: зав.производством ООО "МТК"
A3: _______ Н.В. Менщикова | H3: __________Р.Г. Сахауова
A4: ='7-11'!A4 -> 46034 | C4: понедельник | G4: неделя 1
A5: неделя 1 | C5: Диабет 12 лет и старше
A6: Прием пищи | B6: № рец. | C6: Блюдо | D6: Выход, г | E6: Калорийн | F6: Белки | G6: Жиры | H6: Углеводы
A7: Завтрак
B8: 453 | C8: Каша геркулес молочная б/сахара | D8: 220 | E8: 184.57 | F8: 5.98 | G8: 3.2 | H8: 33.54
B9: 34 | C9: Бутерброд горячий с сыром | D9: 45 | E9: 142.6 | F9: 5 | G9: 8.6 | H9: 10.8
B10: 82 | C10: Фрукты свежие (яблоко) | D10: 100 | E10: 47 | F10: 0.4 | G10: 0.4 | H10: 9.8
B11: 740.1 | C11: Чай с лимоном б/сахара | D11: 200 | E11: 2.4 | F11: 0.2 | G11: 0 | H11: 0.4
B12: 267 | C12: Яйцо вареное | D12: 40 | E12: 63 | F12: 5 | G12: 5 | H12: 0.3
B13: 574 | C13: Хлеб ржаной | D13: 60 | E13: 61.2 | F13: 2 | G13: 0.3 | H13: 12.7
C14: Итого | D14: =SUM(D8:D13) -> 665 | E14: =SUM(E8:E13) -> 500.77 | F14: =SUM(F8:F13) -> 18.58 | G14: =SUM(G8:G13) -> 17.5 | H14: =SUM(H8:H13) -> 67.54
A15: Обед
B16: 53 | C16: Огурцы свежие порционно | D16: 100 | E16: 13.4 | F16: 0.2 | G16: 0 | H16: 0
B17: 139 | C17: Суп картофельный с горохом, с мясом говядины, гренками | D17: 275 | E17: 239.59 | F17: 12.6 | G17: 7.69 | H17: 29.97
B18: 476 | C18: Котлета Домашняя | D18: 100 | E18: 282.38 | F18: 13.49 | G18: 12.36 | H18: 29.66
B19: 114 | C19: Каша перловая рассыпчатая | D19: 180 | E19: 223.2 | F19: 5.42 | G19: 5.08 | H19: 38.92
B20: 699.01 | C20: Напиток апельсиновый б/сахара | D20: 200 | E20: 80 | F20: 0.2 | G20: 0 | H20: 4.5
B21: 574 | C21: Хлеб ржаной | D21: 60 | E21: 61.2 | F21: 2 | G21: 0.3 | H21: 12.7
C22: Итого | D22: =SUM(D16:D21) -> 915 | E22: =SUM(E16:E21) -> 899.77 | F22: =SUM(F16:F21) -> 33.91 | G22: =SUM(G16:G21) -> 25.43 | H22: =SUM(H16:H21) -> 115.75
A23: Полдник
B24: 269 | C24: Омлет запеченый с зеленым горошком | D24: 150 | E24: 215.6 | F24: 11 | G24: 16.6 | H24: 5.4
B25: 82 | C25: Фрукты свежие (яблоко) | D25: 100 | E25: 47 | F25: 0.4 | G25: 0.4 | H25: 9.8
B26: 268 | C26: Кефир | D26: 200 | E26: 100 | F26: 5.8 | G26: 5 | H26: 8
B27: 574 | C27: Хлеб ржаной | D27: 60 | E27: 61.2 | F27: 2 | G27: 0.3 | H27: 12.7
C28: Итого | D28: =SUM(D24:D27) -> 510 | E28: =SUM(E24:E27) -> 423.8 | F28: =SUM(F24:F27) -> 19.2 | G28: =SUM(G24:G27) -> 22.3 | H28: =SUM(H24:H27) -> 35.9
C29: Всего: | E29: =E14+E22+E28 -> 1824.34 | F29: =F14+F22+F28 -> 71.69 | G29: =G14+G22+G28 -> 65.23 | H29: =H14+H22+H28 -> 219.19
A31: Согласовано: | H31: Утверждаю
A32: Директор МБОУ СОШ №4 | H32: зав.производством ООО "МТК"
A33: _______Н.В. Менщикова | H33: __________Р.Г. Сахауова
A34: ='7-11'!A34 -> 46035 | C34: вторник | G34: неделя 1
A35: неделя 1 | C35: Диабет 12 лет и старше
A36: Прием пищи | B36: № рец. | C36: Блюдо | D36: Выход, г | E36: Калорийн | F36: Белки | G36: Жиры | H36: Углеводы
A37: Завтрак
B38: 53 | C38: Огурец свежий порционно | D38: 30 | E38: 4.1 | F38: 0.2 | G38: 0 | H38: 0.7
B39: 503 | C39: Омлет натуральный паровой | D39: 180 | E39: 239.07 | F39: 16.13 | G39: 17.6 | H39: 5.26
B40: 540 | C40: Сыр порционно | D40: 20 | E40: 71.6 | F40: 4.6 | G40: 5.9 | H40: 0
B41: 82/3 | C41: Фрукты свежие (мандарин) | D41: 100 | E41: 38 | F41: 0.8 | G41: 0.2 | H41: 7.5
...
